<?xml version="1.0"?>
<robot name="turtlebot2" xmlns:xacro="http://ros.org/wiki/xacro">

  <!-- Material definitions -->
  <material name="white">
    <color rgba="1 1 1 1"/>
  </material>
  <material name="black">
    <color rgba="0 0 0 1"/>
  </material>
  <material name="red">
    <color rgba="1 0 0 1"/>
  </material>
  <material name="green">
    <color rgba="0 1 0 1"/>
  </material>
  <material name="blue">
    <color rgba="0 0 1 1"/>
  </material>
  <material name="gray">
    <color rgba="0.5 0.5 0.5 1"/>
  </material>

  <!-- BASE LINK -->
  <link name="base_link">
    <visual>
      <geometry>
        <cylinder radius="0.165" length="0.11"/>
      </geometry>
      <material name="black"/>
    </visual>
    <collision>
      <geometry>
        <cylinder radius="0.165" length="0.11"/>
      </geometry>
    </collision>
    <inertial>
      <mass value="2.0"/>
      <inertia ixx="0.01" ixy="0" ixz="0" iyy="0.01" iyz="0" izz="0.02"/>
    </inertial>
  </link>

  <!-- WHEEL LEFT -->
  <link name="wheel_left_link">
    <visual>
      <geometry>
        <cylinder radius="0.0325" length="0.021"/>
      </geometry>
      <material name="gray"/>
    </visual>
    <collision>
      <geometry>
        <cylinder radius="0.0325" length="0.021"/>
      </geometry>
    </collision>
    <inertial>
      <mass value="0.5"/>
      <inertia ixx="0.001" ixy="0" ixz="0" iyy="0.001" iyz="0" izz="0.001"/>
    </inertial>
  </link>

  <joint name="wheel_left_joint" type="continuous">
    <parent link="base_link"/>
    <child link="wheel_left_link"/>
    <origin xyz="0 0.115 -0.0325" rpy="-1.57079633 0 0"/>
    <axis xyz="0 0 1"/>
  </joint>

  <!-- WHEEL RIGHT -->
  <link name="wheel_right_link">
    <visual>
      <geometry>
        <cylinder radius="0.0325" length="0.021"/>
      </geometry>
      <material name="gray"/>
    </visual>
    <collision>
      <geometry>
        <cylinder radius="0.0325" length="0.021"/>
      </geometry>
    </collision>
    <inertial>
      <mass value="0.5"/>
      <inertia ixx="0.001" ixy="0" ixz="0" iyy="0.001" iyz="0" izz="0.001"/>
    </inertial>
  </link>

  <joint name="wheel_right_joint" type="continuous">
    <parent link="base_link"/>
    <child link="wheel_right_link"/>
    <origin xyz="0 -0.115 -0.0325" rpy="-1.57079633 0 0"/>
    <axis xyz="0 0 1"/>
  </joint>

  <!-- CASTER WHEEL -->
  <link name="caster_wheel_link">
    <visual>
      <geometry>
        <sphere radius="0.01"/>
      </geometry>
      <material name="gray"/>
    </visual>
    <collision>
      <geometry>
        <sphere radius="0.01"/>
      </geometry>
    </collision>
    <inertial>
      <mass value="0.1"/>
      <inertia ixx="0.0001" ixy="0" ixz="0" iyy="0.0001" iyz="0" izz="0.0001"/>
    </inertial>
  </link>

  <joint name="caster_wheel_joint" type="fixed">
    <parent link="base_link"/>
    <child link="caster_wheel_link"/>
    <origin xyz="0.12 0 -0.0525" rpy="0 0 0"/>
  </joint>

  <!-- TOP PLATE -->
  <link name="top_plate_link">
    <visual>
      <geometry>
        <box size="0.32 0.32 0.01"/>
      </geometry>
      <material name="white"/>
    </visual>
    <inertial>
      <mass value="0.3"/>
      <inertia ixx="0.001" ixy="0" ixz="0" iyy="0.001" iyz="0" izz="0.002"/>
    </inertial>
  </link>

  <joint name="top_plate_joint" type="fixed">
    <parent link="base_link"/>
    <child link="top_plate_link"/>
    <origin xyz="0 0 0.075" rpy="0 0 0"/>
  </joint>

  <!-- YDLiDAR (Laser Scanner) -->
  <link name="laser_link">
    <visual>
      <geometry>
        <cylinder radius="0.04" length="0.025"/>
      </geometry>
      <material name="red"/>
    </visual>
    <collision>
      <geometry>
        <cylinder radius="0.04" length="0.025"/>
      </geometry>
    </collision>
    <inertial>
      <mass value="0.2"/>
      <inertia ixx="0.001" ixy="0" ixz="0" iyy="0.001" iyz="0" izz="0.001"/>
    </inertial>
  </link>

  <joint name="laser_joint" type="fixed">
    <parent link="top_plate_link"/>
    <child link="laser_link"/>
    <origin xyz="0 0 0.02" rpy="0 0 0"/>
  </joint>

  <!-- RGB CAMERA -->
  <link name="camera_link">
    <visual>
      <geometry>
        <box size="0.05 0.12 0.05"/>
      </geometry>
      <material name="blue"/>
    </visual>
    <collision>
      <geometry>
        <box size="0.05 0.12 0.05"/>
      </geometry>
    </collision>
    <inertial>
      <mass value="0.1"/>
      <inertia ixx="0.0001" ixy="0" ixz="0" iyy="0.0001" iyz="0" izz="0.0001"/>
    </inertial>
  </link>

  <joint name="camera_joint" type="fixed">
    <parent link="top_plate_link"/>
    <child link="camera_link"/>
    <origin xyz="-0.1 0 0.04" rpy="0 0 0"/>
  </joint>

  <!-- CAMERA OPTICAL FRAME (For camera calibration) -->
  <link name="camera_optical_frame"/>

  <joint name="camera_optical_frame_joint" type="fixed">
    <parent link="camera_link"/>
    <child link="camera_optical_frame"/>
    <origin xyz="0 0 0" rpy="-1.57079633 0 -1.57079633"/>
  </joint>

  <!-- IMU -->
  <link name="imu_link">
    <visual>
      <geometry>
        <box size="0.03 0.03 0.03"/>
      </geometry>
      <material name="green"/>
    </visual>
    <inertial>
      <mass value="0.05"/>
      <inertia ixx="0.00001" ixy="0" ixz="0" iyy="0.00001" iyz="0" izz="0.00001"/>
    </inertial>
  </link>

  <joint name="imu_joint" type="fixed">
    <parent link="base_link"/>
    <child link="imu_link"/>
    <origin xyz="0 0 0.05" rpy="0 0 0"/>
  </joint>

</robot>
