<?xml version="1.0"?>
<robot name="test_robot">
  <!-- Base Link -->
  <link name="base_link">
    <visual>
      <geometry>
        <box size="0.3 0.3 0.2"/>
      </geometry>
      <material name="blue">
        <color rgba="0 0 1 1"/>
      </material>
    </visual>
    <collision>
      <geometry>
        <box size="0.3 0.3 0.2"/>
      </geometry>
    </collision>
    <inertial>
      <mass value="10.0"/>
      <inertia ixx="0.1" ixy="0" ixz="0" iyy="0.1" iyz="0" izz="0.1"/>
    </inertial>
  </link>

  <!-- Link 1 -->
  <link name="link1">
    <visual>
      <geometry>
        <cylinder length="0.2" radius="0.05"/>
      </geometry>
      <material name="red">
        <color rgba="1 0 0 1"/>
      </material>
    </visual>
    <collision>
      <geometry>
        <cylinder length="0.2" radius="0.05"/>
      </geometry>
    </collision>
    <inertial>
      <mass value="1.0"/>
      <inertia ixx="0.01" ixy="0" ixz="0" iyy="0.01" iyz="0" izz="0.01"/>
    </inertial>
  </link>

  <!-- Joint 1 -->
  <joint name="joint1" type="revolute">
    <parent link="base_link"/>
    <child link="link1"/>
    <origin xyz="0.15 0 0.1" rpy="0 1.57 0"/>
    <axis xyz="0 0 1"/>
    <limit lower="0" upper="3.14" effort="10" velocity="1"/>
  </joint>

  <!-- Link 2 -->
  <link name="link2">
    <visual>
      <geometry>
        <cylinder length="0.2" radius="0.05"/>
      </geometry>
      <material name="green">
        <color rgba="0 1 0 1"/>
      </material>
    </visual>
    <collision>
      <geometry>
        <cylinder length="0.2" radius="0.05"/>
      </geometry>
    </collision>
    <inertial>
      <mass value="1.0"/>
      <inertia ixx="0.01" ixy="0" ixz="0" iyy="0.01" iyz="0" izz="0.01"/>
    </inertial>
  </link>

  <!-- Joint 2 -->
  <joint name="joint2" type="revolute">
    <parent link="base_link"/>
    <child link="link2"/>
    <origin xyz="-0.15 0 0.1" rpy="0 1.57 0"/>
    <axis xyz="0 0 1"/>
    <limit lower="0" upper="3.14" effort="10" velocity="1"/>
  </joint>

  <!-- Link 3 -->
  <link name="link3">
    <visual>
      <geometry>
        <cylinder length="0.2" radius="0.05"/>
      </geometry>
      <material name="yellow">
        <color rgba="1 1 0 1"/>
      </material>
    </visual>
    <collision>
      <geometry>
        <cylinder length="0.2" radius="0.05"/>
      </geometry>
    </collision>
    <inertial>
      <mass value="1.0"/>
      <inertia ixx="0.01" ixy="0" ixz="0" iyy="0.01" iyz="0" izz="0.01"/>
    </inertial>
  </link>

  <!-- Joint 3 -->
  <joint name="joint3" type="revolute">
    <parent link="base_link"/>
    <child link="link3"/>
    <origin xyz="0 0.15 0.1" rpy="1.57 0 0"/>
    <axis xyz="0 0 1"/>
    <limit lower="0" upper="3.14" effort="10" velocity="1"/>
  </joint>

  <!-- Link 4 -->
  <link name="link4">
    <visual>
      <geometry>
        <cylinder length="0.2" radius="0.05"/>
      </geometry>
      <material name="cyan">
        <color rgba="0 1 1 1"/>
      </material>
    </visual>
    <collision>
      <geometry>
        <cylinder length="0.2" radius="0.05"/>
      </geometry>
    </collision>
    <inertial>
      <mass value="1.0"/>
      <inertia ixx="0.01" ixy="0" ixz="0" iyy="0.01" iyz="0" izz="0.01"/>
    </inertial>
  </link>

  <!-- Joint 4 -->
  <joint name="joint4" type="revolute">
    <parent link="base_link"/>
    <child link="link4"/>
    <origin xyz="0 -0.15 0.1" rpy="1.57 0 0"/>
    <axis xyz="0 0 1"/>
    <limit lower="0" upper="3.14" effort="10" velocity="1"/>
  </joint>

</robot>
